Workbook

Sheet Instructions & Profile
A1: Truth-Importance Scoring Sheet — Paper 2 Pre-Registration
A2: All 100 statements scored BEFORE any human data is collected. This file constitutes the pre-registered framework output. Upload to OSF.io and timestamp before running the human study.
A4: REFERENCE RECEIVER PROFILE (fixed for all 100 statements)
A5: Age | B5: Mid-twenties
A6: Location | B6: Fes, Morocco (mid-sized city)
A7: Education | B7: University level (licence or above)
A8: Language | B8: Arabic/Darija primary, French functional
A9: Media consumption | B9: High — WhatsApp, TikTok, YouTube, Arabic and French press. Skeptical consumer of all platforms. | C9: Informs N_raw, P_var, Q_rel defaults
A10: Religious orientation | B10: Practicing Muslim. Does not conflate religion with traditional medicine or superstition. | C10: Informs Q_rel for religious statements
A11: Economic class | B11: Lower-middle to middle. Lived experience of cost-of-living pressure. | C11: Informs AC_var for economic statements
A12: Political awareness | B12: Informed, cautious about sensitive topics. Not activist. | C12: Informs AB_var for political statements
A13: Prior knowledge P | B13: High on economics, health system, education, social life. Moderate on science/environment. High on history and identity. | C13: P_var per domain: Econ=0.75, Health=0.65, Edu=0.70, Science=0.55, History=0.70, Tech=0.60, BigIdeas=0.50
A14: Relationship to source Q_rel | B14: Default 0.50 (stranger/media). Adjusted per statement where source is personally known or institutionally proximate.
A15: Cognitive/emotional state R | B15: Default 0.55 (engaged, not overwhelmed). Adjusted for statements with high emotional charge.
A17: VARIABLE SCORING GUIDE
A18: CLUSTER 1 — SOURCE CREDIBILITY
A19: B1–B4 (bias vector) | B19: 0=fully biased in this domain, 1=no bias. B1=political, B2=financial, B3=institutional, B4=motivated reasoning. | C19: Default: uniform weights → B_eff = AVERAGE(B1:B4)
A20: C1–C4 (expertise vector) | B20: 0=no expertise, 1=maximum. C1=formal credentials, C2=peer recognition, C3=years practice, C4=novel contributions track record. | C20: Default: uniform weights → C_eff = AVERAGE(C1:C4)
A21: D (rank relative to receiver) | B21: 0=far below receiver, 0.5=equal, 1=far above receiver. | C21: UN Secretary of State to UN = 0.95. Anonymous WhatsApp forward = 0.20.
A22: E (stated confidence) | B22: 0=explicit uncertainty, 0.5=neutral, 1=maximum stated certainty. Self-reported — carries less weight than D by design. | C22: 'I think' = 0.50. 'I confirm' = 0.90.
A23: CLUSTER 2 — STATEMENT PROPERTIES
A24: F (novelty relative to field) | B24: 0=completely standard claim, 1=extraordinary new claim. | C24: Extraordinary claims penalised via F^1.4.
A25: G (internal logical consistency) | B25: 0=internally contradictory, 1=fully coherent. | C25: Necessary but insufficient for truth.
A26: H_f (falsifiability) | B26: 0=in principle untestable, 1=directly verifiable empirically. H_f=0 collapses Stmt to 0 regardless of G. | C26: Simulation theory = 0.02. Clinical trial = 0.95.
A27: J (specificity) | B27: 0=vague generality, 1=precise bounded claim. | C27: 'Some people say prices are high' = 0.20. 'Eggs hit 1.8dh in March 2024' = 0.85.
A28: CLUSTER 3 — DELIVERY
A29: S_r (language register) | B29: 0=completely inappropriate register for receiver, 1=perfect match. | C29: Technical jargon to lay audience = 0.20.
A30: T_r (tone) | B30: 0=grossly inappropriate tone, 1=perfectly appropriate. | C30: Panic tone for routine claim = 0.20.
A31: U_r (expression/nonverbal) | B31: Weakest signal. 0=strong incongruence, 1=full congruence. | C31: Text statements: default 0.60 (no nonverbal signal).
A32: V_r (time context) | B32: 0=worst possible timing, 1=optimal timing. | C32: Breaking news during crisis = 0.95.
A33: W_r (location/setting) | B33: 0=inappropriate/degrading setting, 1=strongest institutional setting. | C33: UN Security Council = 0.99. WhatsApp = 0.35.
A34: X_r (public/private) | B34: 0=statement to oneself (collapses Deliv), 1=maximum public visibility. | C34: Viral tweet = 0.95. Family dinner = 0.45.
A35: CLUSTER 4 — SITUATIONAL
A36: Y_r (general situation) | B36: Background charge of context. 0=maximally hostile background, 1=maximally receptive background.
A37: Z_r (speaker stakes) | B37: 0=nothing to lose, 1=everything to lose. Used via Z_eff = Z*(1−Z*B_eff) — high stakes from biased source are discounted. | C37: Deathbed confession = 0.95. Anonymous post = 0.05.
A38: AA_r (audience composition) | B38: 0=hostile/incompetent audience, 1=perfectly receptive expert audience. Enters with very low exponent (0.2) — weak signal.
A39: AB_r (opposing voices) | B39: 0=maximum active opposition, 1=no opposition. Enters superlinearly (^2.1) — even moderate opposition is a strong negative signal. | C39: Scientific consensus = 0.95. Contested political claim = 0.40.
A40: AD_r (broad stakes) | B40: 0=affects nobody beyond speaker, 1=affects all of humanity. Dominates Sit alongside Z_eff.
A41: CLUSTER 5 — RECEIVER
A42: N_raw (KL divergence proxy) | B42: Continuous. Use these anchors: 0.0–0.3: fully consistent with receiver beliefs, no surprise. 0.5–0.8: mild update, somewhat new. 1.0–1.5: meaningful update, substantially new. 2.0+: strong divergence, contradicts or greatly expands beliefs. Interpolate continuously. | C42: N_norm = 1−EXP(−N). N_perc = inverted U (peaks ~N_norm=0.32). N_imp = monotone increasing.
...

Sheet Scoring
A1: # | B1: Statement | C1: Domain | D1: CLUSTER 1 — SOURCE CREDIBILITY | Q1: CLUSTER 2 — STATEMENT | V1: CLUSTER 3 — DELIVERY | AD1: CLUSTER 4 — SITUATIONAL | AL1: CLUSTER 5 — RECEIVER | AU1: CLUSTER 6 — CORROBORATION | AZ1: T_abs COMPUTATION | BI1: T_perc COMPUTATION | BO1: I COMPUTATION | CC1: OUTPUTS | CF1: NOTES
A2: # | B2: Statement | C2: Domain | D2: B1 Political Bias | E2: B2 Financial Bias | F2: B3 Institutional Bias | G2: B4 Motivated Reasoning | H2: B_eff =AVG(B1:B4) | I2: C1 Credentials | J2: C2 Peer Recog. | K2: C3 Yrs Practice | L2: C4 Track Record | M2: C_eff =AVG(C1:C4) | N2: D Rank vs Receiver | O2: E Stated Confidence | P2: Cred [FORMULA] | Q2: F Novelty | R2: G Consistency | S2: H_f Falsifiability | T2: J Specificity | U2: Stmt [FORMULA] | V2: S_r Language Register | W2: T_r Tone | X2: U_r Expression | Y2: V_r Time Context | Z2: W_r Location | AA2: X_r Public/ Private | AB2: Deliv_raw [FORMULA] | AC2: Deliv =SQRT(raw) | AD2: Y_r Gen. Situation | AE2: Z_r Speaker Stakes | AF2: Z_eff [FORMULA] | AG2: AA_r Audience | AH2: AB_r Opposition | AI2: AD_r Broad Stakes | AJ2: Sit_raw [FORMULA] | AK2: Sit =SQRT(raw) | AL2: N_raw KL Proxy | AM2: N_norm [FORMULA] | AN2: N_perc [FORMULA] | AO2: P Prior Knowledge | AP2: Q_rel Relationship | AQ2: R_var Cog/Emo State | AR2: AC_var Personal Conseq. | AS2: Recv_raw [FORMULA] | AT2: Recv =CBRT(raw) | AU2: K_base Best LR | AV2: K_n # Sources | AW2: K_comb [FORMULA] | AX2: L Estab. Knowledge | AY2: M Physical Evidence | AZ2: Prior P(A) | BA2: Odds Prior | BB2: Λ_Cred | BC2: Λ_Stmt | BD2: Λ_K | BE2: Λ_L | BF2: Λ_M | BG2: Odds Final | BH2: T_abs [OUTPUT] | BI2: Odds T_abs | BJ2: Λ_Deliv | BK2: Λ_Sit | BL2: Λ_Recv | BM2: Odds T_perc | BN2: T_perc [OUTPUT] | BO2: Deliv tilde | BP2: Sit tilde | BQ2: N_imp [FORMULA] | BR2: Recv_imp raw | BS2: Recv tilde | BT2: Odds I prior | BU2: Λ_Deliv_I | BV2: Λ_Sit_I | BW2: Λ_Recv_I | BX2: Odds I_context | BY2: I_context [FORMULA] | BZ2: Λ_T [FORMULA] | CA2: Odds I_final | CB2: I [OUTPUT] | CC2: T_abs SUMMARY | CD2: T_perc SUMMARY | CE2: I SUMMARY | CF2: Notes / Variable Justification
A3: 1 | B3: In many Moroccan public hospitals, patients are told to buy their own medicine from a pharmacy because the hospital has run out. | C3: Health | D3: 0.85 | E3: 0.85 | F3: 0.75 | G3: 0.82 | H3: =IFERROR(AVERAGE(D3,E3,F3,G3),"") | I3: 0.7 | J3: 0.65 | K3: 0.7 | L3: 0.68 | M3: =IFERROR(AVERAGE(I3,J3,K3,L3),"") | N3: 0.6 | O3: 0.8 | P3: =IFERROR(IF(H3=0,0,H3^(H3^(-0.5)))*SQRT(M3)*((4*N3+O3)/5),"") | Q3: 0.3 | R3: 0.92 | S3: 0.88 | T3: 0.82 | U3: =IFERROR(((Q3^1.4+T3)/2)*R3*(1-EXP(-4.605*S3)),"") | V3: 0.65 | W3: 0.7 | X3: 0.6 | Y3: 0.72 | Z3: 0.45 | AA3: 0.72 | AB3: =IFERROR(Z3*(Y3*AA3^1.1)^1.1*((3*V3+2*W3+X3)/6)^0.5,"") | AC3: =IFERROR(SQRT(AB3),"") | AD3: 0.7 | AE3: 0.4 | AF3: =IFERROR(AE3*(1-AE3*H3),"") | AG3: 0.65 | AH3: 0.8 | AI3: 0.75 | AJ3: =IFERROR(AH3^2.1*AG3^0.2*(2*AF3+3*AI3+AD3)/6,"") | AK3: =IFERROR(SQRT(AJ3),"") | AL3: 0.2 | AM3: =IFERROR(1-EXP(-AL3),"") | AN3: =IFERROR(4.18*AM3^0.7*(1-AM3)^1.5,"") | AO3: 0.65 | AP3: 0.5 | AQ3: 0.65 | AR3: 0.85 | AS3: =IFERROR(AN3^(1-AO3)*AP3*(4*AQ3*(1-AQ3))*AR3^1.15,"") | AT3: =IFERROR(AS3^(1/3),"") | AU3: 1.8 | AV3: 3 | AW3: =IFERROR(IF(AV3<=1,AU3,AU3*(1+(AV3-1)*0.6)),"") | AX3: 0.85 | AY3: 0.4 | AZ3: 0.5 | BA3: =IFERROR(AZ3/(1-AZ3),"") | BB3: =IFERROR(EXP((P3-0.301)/(0.301*(1-0.301))),"") | BC3: =IFERROR(EXP((U3-0.354)/(0.354*(1-0.354))),"") | BD3: =IFERROR(AW3,"") | BE3: =IFERROR(EXP((AX3-0.75)/(0.75*(1-0.75))),"") | BF3: =IFERROR(EXP((AY3-0.5)/(0.5*(1-0.5))),"") | BG3: =IFERROR(BA3*BB3*BC3*BD3*BE3*BF3,"") | BH3: =IFERROR(BG3/(1+BG3),"") | BI3: =IFERROR(IF(BH3>=1,1E9,BH3/(1-BH3)),"") | BJ3: =IFERROR(EXP((AC3-0.372)/(0.372*(1-0.372))),"") | BK3: =IFERROR(EXP((AK3-0.415)/(0.415*(1-0.415))),"") | BL3: =IFERROR(EXP((AT3-0.405)/(0.405*(1-0.405))),"") | BM3: =IFERROR(BI3*BJ3*BK3*BL3,"") | BN3: =IFERROR(BM3/(1+BM3),"") | BO3: =IFERROR(IF(AC3>=1,0.999,1-EXP(1-(1-AC3)^(-0.8))),"") | BP3: =IFERROR(IF(AK3>=1,0.999,1-EXP(1-(1-AK3)^(-0.75))),"") | BQ3: =IFERROR(1-EXP(-AL3*(1+AL3)),"") | BR3: =IFERROR(BQ3^(1-AO3)*AP3*(4*AQ3*(1-AQ3))*AR3^1.15,"") | BS3: =IFERROR(IF(BR3^(1/3)>=1,0.999,1-EXP(1-(1-BR3^(1/3))^(-0.7))),"") | BT3: =1 | BU3: =IFERROR(EXP((BO3-0.372)/(0.372*(1-0.372))),"") | BV3: =IFERROR(EXP((BP3-0.415)/(0.415*(1-0.415))),"") | BW3: =IFERROR(EXP((BS3-0.405)/(0.405*(1-0.405))),"") | BX3: =IFERROR(BT3*BU3*BV3*BW3,"") | BY3: =IFERROR(BX3/(1+BX3),"") | BZ3: =IFERROR(EXP(0.15*(SQRT(BH3)-0.5)/(0.5*0.5)),"") | CA3: =IFERROR(IF(BY3>=1,1E9,BY3/(1-BY3)*BZ3),"") | CB3: =IFERROR(CA3/(1+CA3),"") | CC3: =BH3 | CD3: =BN3 | CE3: =CB3 | CF3: Lived experience. Very widely known. High personal consequence for health.
A4: 2 | B4: Getting a specialist appointment in a Moroccan public hospital can take several months to over a year. | C4: Health | D4: 0.85 | E4: 0.85 | F4: 0.75 | G4: 0.82 | H4: =IFERROR(AVERAGE(D4,E4,F4,G4),"") | I4: 0.7 | J4: 0.65 | K4: 0.7 | L4: 0.68 | M4: =IFERROR(AVERAGE(I4,J4,K4,L4),"") | N4: 0.6 | O4: 0.75 | P4: =IFERROR(IF(H4=0,0,H4^(H4^(-0.5)))*SQRT(M4)*((4*N4+O4)/5),"") | Q4: 0.3 | R4: 0.9 | S4: 0.85 | T4: 0.8 | U4: =IFERROR(((Q4^1.4+T4)/2)*R4*(1-EXP(-4.605*S4)),"") | V4: 0.65 | W4: 0.7 | X4: 0.6 | Y4: 0.7 | Z4: 0.45 | AA4: 0.7 | AB4: =IFERROR(Z4*(Y4*AA4^1.1)^1.1*((3*V4+2*W4+X4)/6)^0.5,"") | AC4: =IFERROR(SQRT(AB4),"") | AD4: 0.68 | AE4: 0.35 | AF4: =IFERROR(AE4*(1-AE4*H4),"") | AG4: 0.65 | AH4: 0.78 | AI4: 0.72 | AJ4: =IFERROR(AH4^2.1*AG4^0.2*(2*AF4+3*AI4+AD4)/6,"") | AK4: =IFERROR(SQRT(AJ4),"") | AL4: 0.25 | AM4: =IFERROR(1-EXP(-AL4),"") | AN4: =IFERROR(4.18*AM4^0.7*(1-AM4)^1.5,"") | AO4: 0.65 | AP4: 0.5 | AQ4: 0.65 | AR4: 0.82 | AS4: =IFERROR(AN4^(1-AO4)*AP4*(4*AQ4*(1-AQ4))*AR4^1.15,"") | AT4: =IFERROR(AS4^(1/3),"") | AU4: 1.7 | AV4: 3 | AW4: =IFERROR(IF(AV4<=1,AU4,AU4*(1+(AV4-1)*0.6)),"") | AX4: 0.85 | AY4: 0.35 | AZ4: 0.5 | BA4: =IFERROR(AZ4/(1-AZ4),"") | BB4: =IFERROR(EXP((P4-0.301)/(0.301*(1-0.301))),"") | BC4: =IFERROR(EXP((U4-0.354)/(0.354*(1-0.354))),"") | BD4: =IFERROR(AW4,"") | BE4: =IFERROR(EXP((AX4-0.75)/(0.75*(1-0.75))),"") | BF4: =IFERROR(EXP((AY4-0.5)/(0.5*(1-0.5))),"") | BG4: =IFERROR(BA4*BB4*BC4*BD4*BE4*BF4,"") | BH4: =IFERROR(BG4/(1+BG4),"") | BI4: =IFERROR(IF(BH4>=1,1E9,BH4/(1-BH4)),"") | BJ4: =IFERROR(EXP((AC4-0.372)/(0.372*(1-0.372))),"") | BK4: =IFERROR(EXP((AK4-0.415)/(0.415*(1-0.415))),"") | BL4: =IFERROR(EXP((AT4-0.405)/(0.405*(1-0.405))),"") | BM4: =IFERROR(BI4*BJ4*BK4*BL4,"") | BN4: =IFERROR(BM4/(1+BM4),"") | BO4: =IFERROR(IF(AC4>=1,0.999,1-EXP(1-(1-AC4)^(-0.8))),"") | BP4: =IFERROR(IF(AK4>=1,0.999,1-EXP(1-(1-AK4)^(-0.75))),"") | BQ4: =IFERROR(1-EXP(-AL4*(1+AL4)),"") | BR4: =IFERROR(BQ4^(1-AO4)*AP4*(4*AQ4*(1-AQ4))*AR4^1.15,"") | BS4: =IFERROR(IF(BR4^(1/3)>=1,0.999,1-EXP(1-(1-BR4^(1/3))^(-0.7))),"") | BT4: =1 | BU4: =IFERROR(EXP((BO4-0.372)/(0.372*(1-0.372))),"") | BV4: =IFERROR(EXP((BP4-0.415)/(0.415*(1-0.415))),"") | BW4: =IFERROR(EXP((BS4-0.405)/(0.405*(1-0.405))),"") | BX4: =IFERROR(BT4*BU4*BV4*BW4,"") | BY4: =IFERROR(BX4/(1+BX4),"") | BZ4: =IFERROR(EXP(0.15*(SQRT(BH4)-0.5)/(0.5*0.5)),"") | CA4: =IFERROR(IF(BY4>=1,1E9,BY4/(1-BY4)*BZ4),"") | CB4: =IFERROR(CA4/(1+CA4),"") | CC4: =BH4 | CD4: =BN4 | CE4: =CB4 | CF4: Widely known from personal/family experience. High frustration context.
A5: 3 | B5: The quality of care you receive in a Moroccan hospital depends more on who you know than on your medical card. | C5: Health | D5: 0.82 | E5: 0.82 | F5: 0.72 | G5: 0.8 | H5: =IFERROR(AVERAGE(D5,E5,F5,G5),"") | I5: 0.68 | J5: 0.63 | K5: 0.68 | L5: 0.65 | M5: =IFERROR(AVERAGE(I5,J5,K5,L5),"") | N5: 0.55 | O5: 0.72 | P5: =IFERROR(IF(H5=0,0,H5^(H5^(-0.5)))*SQRT(M5)*((4*N5+O5)/5),"") | Q5: 0.4 | R5: 0.85 | S5: 0.8 | T5: 0.78 | U5: =IFERROR(((Q5^1.4+T5)/2)*R5*(1-EXP(-4.605*S5)),"") | V5: 0.65 | W5: 0.68 | X5: 0.6 | Y5: 0.7 | Z5: 0.45 | AA5: 0.7 | AB5: =IFERROR(Z5*(Y5*AA5^1.1)^1.1*((3*V5+2*W5+X5)/6)^0.5,"") | AC5: =IFERROR(SQRT(AB5),"") | AD5: 0.65 | AE5: 0.35 | AF5: =IFERROR(AE5*(1-AE5*H5),"") | AG5: 0.62 | AH5: 0.72 | AI5: 0.7 | AJ5: =IFERROR(AH5^2.1*AG5^0.2*(2*AF5+3*AI5+AD5)/6,"") | AK5: =IFERROR(SQRT(AJ5),"") | AL5: 0.35 | AM5: =IFERROR(1-EXP(-AL5),"") | AN5: =IFERROR(4.18*AM5^0.7*(1-AM5)^1.5,"") | AO5: 0.65 | AP5: 0.5 | AQ5: 0.6 | AR5: 0.8 | AS5: =IFERROR(AN5^(1-AO5)*AP5*(4*AQ5*(1-AQ5))*AR5^1.15,"") | AT5: =IFERROR(AS5^(1/3),"") | AU5: 1.5 | AV5: 2 | AW5: =IFERROR(IF(AV5<=1,AU5,AU5*(1+(AV5-1)*0.6)),"") | AX5: 0.8 | AY5: 0.3 | AZ5: 0.5 | BA5: =IFERROR(AZ5/(1-AZ5),"") | BB5: =IFERROR(EXP((P5-0.301)/(0.301*(1-0.301))),"") | BC5: =IFERROR(EXP((U5-0.354)/(0.354*(1-0.354))),"") | BD5: =IFERROR(AW5,"") | BE5: =IFERROR(EXP((AX5-0.75)/(0.75*(1-0.75))),"") | BF5: =IFERROR(EXP((AY5-0.5)/(0.5*(1-0.5))),"") | BG5: =IFERROR(BA5*BB5*BC5*BD5*BE5*BF5,"") | BH5: =IFERROR(BG5/(1+BG5),"") | BI5: =IFERROR(IF(BH5>=1,1E9,BH5/(1-BH5)),"") | BJ5: =IFERROR(EXP((AC5-0.372)/(0.372*(1-0.372))),"") | BK5: =IFERROR(EXP((AK5-0.415)/(0.415*(1-0.415))),"") | BL5: =IFERROR(EXP((AT5-0.405)/(0.405*(1-0.405))),"") | BM5: =IFERROR(BI5*BJ5*BK5*BL5,"") | BN5: =IFERROR(BM5/(1+BM5),"") | BO5: =IFERROR(IF(AC5>=1,0.999,1-EXP(1-(1-AC5)^(-0.8))),"") | BP5: =IFERROR(IF(AK5>=1,0.999,1-EXP(1-(1-AK5)^(-0.75))),"") | BQ5: =IFERROR(1-EXP(-AL5*(1+AL5)),"") | BR5: =IFERROR(BQ5^(1-AO5)*AP5*(4*AQ5*(1-AQ5))*AR5^1.15,"") | BS5: =IFERROR(IF(BR5^(1/3)>=1,0.999,1-EXP(1-(1-BR5^(1/3))^(-0.7))),"") | BT5: =1 | BU5: =IFERROR(EXP((BO5-0.372)/(0.372*(1-0.372))),"") | BV5: =IFERROR(EXP((BP5-0.415)/(0.415*(1-0.415))),"") | BW5: =IFERROR(EXP((BS5-0.405)/(0.405*(1-0.405))),"") | BX5: =IFERROR(BT5*BU5*BV5*BW5,"") | BY5: =IFERROR(BX5/(1+BX5),"") | BZ5: =IFERROR(EXP(0.15*(SQRT(BH5)-0.5)/(0.5*0.5)),"") | CA5: =IFERROR(IF(BY5>=1,1E9,BY5/(1-BY5)*BZ5),"") | CB5: =IFERROR(CA5/(1+CA5),"") | CC5: =BH5 | CD5: =BN5 | CE5: =CB5 | CF5: Widely believed. Decent opposition - some deny systemic nature.
A6: 4 | B6: There are regions in Morocco where reaching the nearest doctor means a long, difficult trip, not a quick visit. | C6: Health | D6: 0.85 | E6: 0.85 | F6: 0.75 | G6: 0.82 | H6: =IFERROR(AVERAGE(D6,E6,F6,G6),"") | I6: 0.68 | J6: 0.65 | K6: 0.68 | L6: 0.65 | M6: =IFERROR(AVERAGE(I6,J6,K6,L6),"") | N6: 0.58 | O6: 0.72 | P6: =IFERROR(IF(H6=0,0,H6^(H6^(-0.5)))*SQRT(M6)*((4*N6+O6)/5),"") | Q6: 0.35 | R6: 0.9 | S6: 0.85 | T6: 0.78 | U6: =IFERROR(((Q6^1.4+T6)/2)*R6*(1-EXP(-4.605*S6)),"") | V6: 0.62 | W6: 0.68 | X6: 0.6 | Y6: 0.68 | Z6: 0.45 | AA6: 0.68 | AB6: =IFERROR(Z6*(Y6*AA6^1.1)^1.1*((3*V6+2*W6+X6)/6)^0.5,"") | AC6: =IFERROR(SQRT(AB6),"") | AD6: 0.62 | AE6: 0.32 | AF6: =IFERROR(AE6*(1-AE6*H6),"") | AG6: 0.6 | AH6: 0.82 | AI6: 0.68 | AJ6: =IFERROR(AH6^2.1*AG6^0.2*(2*AF6+3*AI6+AD6)/6,"") | AK6: =IFERROR(SQRT(AJ6),"") | AL6: 0.5 | AM6: =IFERROR(1-EXP(-AL6),"") | AN6: =IFERROR(4.18*AM6^0.7*(1-AM6)^1.5,"") | AO6: 0.6 | AP6: 0.45 | AQ6: 0.55 | AR6: 0.55 | AS6: =IFERROR(AN6^(1-AO6)*AP6*(4*AQ6*(1-AQ6))*AR6^1.15,"") | AT6: =IFERROR(AS6^(1/3),"") | AU6: 1.6 | AV6: 2 | AW6: =IFERROR(IF(AV6<=1,AU6,AU6*(1+(AV6-1)*0.6)),"") | AX6: 0.88 | AY6: 0.35 | AZ6: 0.5 | BA6: =IFERROR(AZ6/(1-AZ6),"") | BB6: =IFERROR(EXP((P6-0.301)/(0.301*(1-0.301))),"") | BC6: =IFERROR(EXP((U6-0.354)/(0.354*(1-0.354))),"") | BD6: =IFERROR(AW6,"") | BE6: =IFERROR(EXP((AX6-0.75)/(0.75*(1-0.75))),"") | BF6: =IFERROR(EXP((AY6-0.5)/(0.5*(1-0.5))),"") | BG6: =IFERROR(BA6*BB6*BC6*BD6*BE6*BF6,"") | BH6: =IFERROR(BG6/(1+BG6),"") | BI6: =IFERROR(IF(BH6>=1,1E9,BH6/(1-BH6)),"") | BJ6: =IFERROR(EXP((AC6-0.372)/(0.372*(1-0.372))),"") | BK6: =IFERROR(EXP((AK6-0.415)/(0.415*(1-0.415))),"") | BL6: =IFERROR(EXP((AT6-0.405)/(0.405*(1-0.405))),"") | BM6: =IFERROR(BI6*BJ6*BK6*BL6,"") | BN6: =IFERROR(BM6/(1+BM6),"") | BO6: =IFERROR(IF(AC6>=1,0.999,1-EXP(1-(1-AC6)^(-0.8))),"") | BP6: =IFERROR(IF(AK6>=1,0.999,1-EXP(1-(1-AK6)^(-0.75))),"") | BQ6: =IFERROR(1-EXP(-AL6*(1+AL6)),"") | BR6: =IFERROR(BQ6^(1-AO6)*AP6*(4*AQ6*(1-AQ6))*AR6^1.15,"") | BS6: =IFERROR(IF(BR6^(1/3)>=1,0.999,1-EXP(1-(1-BR6^(1/3))^(-0.7))),"") | BT6: =1 | BU6: =IFERROR(EXP((BO6-0.372)/(0.372*(1-0.372))),"") | BV6: =IFERROR(EXP((BP6-0.415)/(0.415*(1-0.415))),"") | BW6: =IFERROR(EXP((BS6-0.405)/(0.405*(1-0.405))),"") | BX6: =IFERROR(BT6*BU6*BV6*BW6,"") | BY6: =IFERROR(BX6/(1+BX6),"") | BZ6: =IFERROR(EXP(0.15*(SQRT(BH6)-0.5)/(0.5*0.5)),"") | CA6: =IFERROR(IF(BY6>=1,1E9,BY6/(1-BY6)*BZ6),"") | CB6: =IFERROR(CA6/(1+CA6),"") | CC6: =BH6 | CD6: =BN6 | CE6: =CB6 | CF6: Known fact. Less personally salient for urban Fes receiver.
A7: 5 | B7: A doctor in a Moroccan public hospital sees so many patients per day that each consultation gets rushed down to just a few minutes. | C7: Health | D7: 0.85 | E7: 0.85 | F7: 0.75 | G7: 0.82 | H7: =IFERROR(AVERAGE(D7,E7,F7,G7),"") | I7: 0.7 | J7: 0.65 | K7: 0.7 | L7: 0.68 | M7: =IFERROR(AVERAGE(I7,J7,K7,L7),"") | N7: 0.6 | O7: 0.8 | P7: =IFERROR(IF(H7=0,0,H7^(H7^(-0.5)))*SQRT(M7)*((4*N7+O7)/5),"") | Q7: 0.3 | R7: 0.92 | S7: 0.88 | T7: 0.82 | U7: =IFERROR(((Q7^1.4+T7)/2)*R7*(1-EXP(-4.605*S7)),"") | V7: 0.65 | W7: 0.7 | X7: 0.6 | Y7: 0.72 | Z7: 0.45 | AA7: 0.72 | AB7: =IFERROR(Z7*(Y7*AA7^1.1)^1.1*((3*V7+2*W7+X7)/6)^0.5,"") | AC7: =IFERROR(SQRT(AB7),"") | AD7: 0.7 | AE7: 0.38 | AF7: =IFERROR(AE7*(1-AE7*H7),"") | AG7: 0.65 | AH7: 0.78 | AI7: 0.72 | AJ7: =IFERROR(AH7^2.1*AG7^0.2*(2*AF7+3*AI7+AD7)/6,"") | AK7: =IFERROR(SQRT(AJ7),"") | AL7: 0.2 | AM7: =IFERROR(1-EXP(-AL7),"") | AN7: =IFERROR(4.18*AM7^0.7*(1-AM7)^1.5,"") | AO7: 0.65 | AP7: 0.5 | AQ7: 0.65 | AR7: 0.82 | AS7: =IFERROR(AN7^(1-AO7)*AP7*(4*AQ7*(1-AQ7))*AR7^1.15,"") | AT7: =IFERROR(AS7^(1/3),"") | AU7: 1.7 | AV7: 2 | AW7: =IFERROR(IF(AV7<=1,AU7,AU7*(1+(AV7-1)*0.6)),"") | AX7: 0.85 | AY7: 0.35 | AZ7: 0.5 | BA7: =IFERROR(AZ7/(1-AZ7),"") | BB7: =IFERROR(EXP((P7-0.301)/(0.301*(1-0.301))),"") | BC7: =IFERROR(EXP((U7-0.354)/(0.354*(1-0.354))),"") | BD7: =IFERROR(AW7,"") | BE7: =IFERROR(EXP((AX7-0.75)/(0.75*(1-0.75))),"") | BF7: =IFERROR(EXP((AY7-0.5)/(0.5*(1-0.5))),"") | BG7: =IFERROR(BA7*BB7*BC7*BD7*BE7*BF7,"") | BH7: =IFERROR(BG7/(1+BG7),"") | BI7: =IFERROR(IF(BH7>=1,1E9,BH7/(1-BH7)),"") | BJ7: =IFERROR(EXP((AC7-0.372)/(0.372*(1-0.372))),"") | BK7: =IFERROR(EXP((AK7-0.415)/(0.415*(1-0.415))),"") | BL7: =IFERROR(EXP((AT7-0.405)/(0.405*(1-0.405))),"") | BM7: =IFERROR(BI7*BJ7*BK7*BL7,"") | BN7: =IFERROR(BM7/(1+BM7),"") | BO7: =IFERROR(IF(AC7>=1,0.999,1-EXP(1-(1-AC7)^(-0.8))),"") | BP7: =IFERROR(IF(AK7>=1,0.999,1-EXP(1-(1-AK7)^(-0.75))),"") | BQ7: =IFERROR(1-EXP(-AL7*(1+AL7)),"") | BR7: =IFERROR(BQ7^(1-AO7)*AP7*(4*AQ7*(1-AQ7))*AR7^1.15,"") | BS7: =IFERROR(IF(BR7^(1/3)>=1,0.999,1-EXP(1-(1-BR7^(1/3))^(-0.7))),"") | BT7: =1 | BU7: =IFERROR(EXP((BO7-0.372)/(0.372*(1-0.372))),"") | BV7: =IFERROR(EXP((BP7-0.415)/(0.415*(1-0.415))),"") | BW7: =IFERROR(EXP((BS7-0.405)/(0.405*(1-0.405))),"") | BX7: =IFERROR(BT7*BU7*BV7*BW7,"") | BY7: =IFERROR(BX7/(1+BX7),"") | BZ7: =IFERROR(EXP(0.15*(SQRT(BH7)-0.5)/(0.5*0.5)),"") | CA7: =IFERROR(IF(BY7>=1,1E9,BY7/(1-BY7)*BZ7),"") | CB7: =IFERROR(CA7/(1+CA7),"") | CC7: =BH7 | CD7: =BN7 | CE7: =CB7 | CF7: Personally experienced. Very credible from lived experience.
A8: 6 | B8: Private clinics in Morocco are expensive but often face the same medicine shortages as public hospitals. | C8: Health | D8: 0.82 | E8: 0.82 | F8: 0.72 | G8: 0.8 | H8: =IFERROR(AVERAGE(D8,E8,F8,G8),"") | I8: 0.68 | J8: 0.63 | K8: 0.68 | L8: 0.65 | M8: =IFERROR(AVERAGE(I8,J8,K8,L8),"") | N8: 0.55 | O8: 0.7 | P8: =IFERROR(IF(H8=0,0,H8^(H8^(-0.5)))*SQRT(M8)*((4*N8+O8)/5),"") | Q8: 0.45 | R8: 0.88 | S8: 0.85 | T8: 0.75 | U8: =IFERROR(((Q8^1.4+T8)/2)*R8*(1-EXP(-4.605*S8)),"") | V8: 0.62 | W8: 0.68 | X8: 0.6 | Y8: 0.68 | Z8: 0.45 | AA8: 0.68 | AB8: =IFERROR(Z8*(Y8*AA8^1.1)^1.1*((3*V8+2*W8+X8)/6)^0.5,"") | AC8: =IFERROR(SQRT(AB8),"") | AD8: 0.62 | AE8: 0.35 | AF8: =IFERROR(AE8*(1-AE8*H8),"") | AG8: 0.6 | AH8: 0.72 | AI8: 0.65 | AJ8: =IFERROR(AH8^2.1*AG8^0.2*(2*AF8+3*AI8+AD8)/6,"") | AK8: =IFERROR(SQRT(AJ8),"") | AL8: 0.8 | AM8: =IFERROR(1-EXP(-AL8),"") | AN8: =IFERROR(4.18*AM8^0.7*(1-AM8)^1.5,"") | AO8: 0.62 | AP8: 0.48 | AQ8: 0.58 | AR8: 0.75 | AS8: =IFERROR(AN8^(1-AO8)*AP8*(4*AQ8*(1-AQ8))*AR8^1.15,"") | AT8: =IFERROR(AS8^(1/3),"") | AU8: 1.4 | AV8: 2 | AW8: =IFERROR(IF(AV8<=1,AU8,AU8*(1+(AV8-1)*0.6)),"") | AX8: 0.78 | AY8: 0.3 | AZ8: 0.5 | BA8: =IFERROR(AZ8/(1-AZ8),"") | BB8: =IFERROR(EXP((P8-0.301)/(0.301*(1-0.301))),"") | BC8: =IFERROR(EXP((U8-0.354)/(0.354*(1-0.354))),"") | BD8: =IFERROR(AW8,"") | BE8: =IFERROR(EXP((AX8-0.75)/(0.75*(1-0.75))),"") | BF8: =IFERROR(EXP((AY8-0.5)/(0.5*(1-0.5))),"") | BG8: =IFERROR(BA8*BB8*BC8*BD8*BE8*BF8,"") | BH8: =IFERROR(BG8/(1+BG8),"") | BI8: =IFERROR(IF(BH8>=1,1E9,BH8/(1-BH8)),"") | BJ8: =IFERROR(EXP((AC8-0.372)/(0.372*(1-0.372))),"") | BK8: =IFERROR(EXP((AK8-0.415)/(0.415*(1-0.415))),"") | BL8: =IFERROR(EXP((AT8-0.405)/(0.405*(1-0.405))),"") | BM8: =IFERROR(BI8*BJ8*BK8*BL8,"") | BN8: =IFERROR(BM8/(1+BM8),"") | BO8: =IFERROR(IF(AC8>=1,0.999,1-EXP(1-(1-AC8)^(-0.8))),"") | BP8: =IFERROR(IF(AK8>=1,0.999,1-EXP(1-(1-AK8)^(-0.75))),"") | BQ8: =IFERROR(1-EXP(-AL8*(1+AL8)),"") | BR8: =IFERROR(BQ8^(1-AO8)*AP8*(4*AQ8*(1-AQ8))*AR8^1.15,"") | BS8: =IFERROR(IF(BR8^(1/3)>=1,0.999,1-EXP(1-(1-BR8^(1/3))^(-0.7))),"") | BT8: =1 | BU8: =IFERROR(EXP((BO8-0.372)/(0.372*(1-0.372))),"") | BV8: =IFERROR(EXP((BP8-0.415)/(0.415*(1-0.415))),"") | BW8: =IFERROR(EXP((BS8-0.405)/(0.405*(1-0.405))),"") | BX8: =IFERROR(BT8*BU8*BV8*BW8,"") | BY8: =IFERROR(BX8/(1+BX8),"") | BZ8: =IFERROR(EXP(0.15*(SQRT(BH8)-0.5)/(0.5*0.5)),"") | CA8: =IFERROR(IF(BY8>=1,1E9,BY8/(1-BY8)*BZ8),"") | CB8: =IFERROR(CA8/(1+CA8),"") | CC8: =BH8 | CD8: =BN8 | CE8: =CB8 | CF8: Somewhat counterintuitive - people expect private to be better.
A9: 7 | B9: Morocco has far fewer doctors per person than international health bodies consider safe. | C9: Health | D9: 0.82 | E9: 0.82 | F9: 0.75 | G9: 0.8 | H9: =IFERROR(AVERAGE(D9,E9,F9,G9),"") | I9: 0.68 | J9: 0.65 | K9: 0.68 | L9: 0.65 | M9: =IFERROR(AVERAGE(I9,J9,K9,L9),"") | N9: 0.58 | O9: 0.72 | P9: =IFERROR(IF(H9=0,0,H9^(H9^(-0.5)))*SQRT(M9)*((4*N9+O9)/5),"") | Q9: 0.35 | R9: 0.9 | S9: 0.85 | T9: 0.78 | U9: =IFERROR(((Q9^1.4+T9)/2)*R9*(1-EXP(-4.605*S9)),"") | V9: 0.62 | W9: 0.68 | X9: 0.6 | Y9: 0.68 | Z9: 0.45 | AA9: 0.68 | AB9: =IFERROR(Z9*(Y9*AA9^1.1)^1.1*((3*V9+2*W9+X9)/6)^0.5,"") | AC9: =IFERROR(SQRT(AB9),"") | AD9: 0.65 | AE9: 0.35 | AF9: =IFERROR(AE9*(1-AE9*H9),"") | AG9: 0.62 | AH9: 0.8 | AI9: 0.68 | AJ9: =IFERROR(AH9^2.1*AG9^0.2*(2*AF9+3*AI9+AD9)/6,"") | AK9: =IFERROR(SQRT(AJ9),"") | AL9: 0.4 | AM9: =IFERROR(1-EXP(-AL9),"") | AN9: =IFERROR(4.18*AM9^0.7*(1-AM9)^1.5,"") | AO9: 0.63 | AP9: 0.48 | AQ9: 0.58 | AR9: 0.72 | AS9: =IFERROR(AN9^(1-AO9)*AP9*(4*AQ9*(1-AQ9))*AR9^1.15,"") | AT9: =IFERROR(AS9^(1/3),"") | AU9: 2 | AV9: 3 | AW9: =IFERROR(IF(AV9<=1,AU9,AU9*(1+(AV9-1)*0.6)),"") | AX9: 0.88 | AY9: 0.42 | AZ9: 0.5 | BA9: =IFERROR(AZ9/(1-AZ9),"") | BB9: =IFERROR(EXP((P9-0.301)/(0.301*(1-0.301))),"") | BC9: =IFERROR(EXP((U9-0.354)/(0.354*(1-0.354))),"") | BD9: =IFERROR(AW9,"") | BE9: =IFERROR(EXP((AX9-0.75)/(0.75*(1-0.75))),"") | BF9: =IFERROR(EXP((AY9-0.5)/(0.5*(1-0.5))),"") | BG9: =IFERROR(BA9*BB9*BC9*BD9*BE9*BF9,"") | BH9: =IFERROR(BG9/(1+BG9),"") | BI9: =IFERROR(IF(BH9>=1,1E9,BH9/(1-BH9)),"") | BJ9: =IFERROR(EXP((AC9-0.372)/(0.372*(1-0.372))),"") | BK9: =IFERROR(EXP((AK9-0.415)/(0.415*(1-0.415))),"") | BL9: =IFERROR(EXP((AT9-0.405)/(0.405*(1-0.405))),"") | BM9: =IFERROR(BI9*BJ9*BK9*BL9,"") | BN9: =IFERROR(BM9/(1+BM9),"") | BO9: =IFERROR(IF(AC9>=1,0.999,1-EXP(1-(1-AC9)^(-0.8))),"") | BP9: =IFERROR(IF(AK9>=1,0.999,1-EXP(1-(1-AK9)^(-0.75))),"") | BQ9: =IFERROR(1-EXP(-AL9*(1+AL9)),"") | BR9: =IFERROR(BQ9^(1-AO9)*AP9*(4*AQ9*(1-AQ9))*AR9^1.15,"") | BS9: =IFERROR(IF(BR9^(1/3)>=1,0.999,1-EXP(1-(1-BR9^(1/3))^(-0.7))),"") | BT9: =1 | BU9: =IFERROR(EXP((BO9-0.372)/(0.372*(1-0.372))),"") | BV9: =IFERROR(EXP((BP9-0.415)/(0.415*(1-0.415))),"") | BW9: =IFERROR(EXP((BS9-0.405)/(0.405*(1-0.405))),"") | BX9: =IFERROR(BT9*BU9*BV9*BW9,"") | BY9: =IFERROR(BX9/(1+BX9),"") | BZ9: =IFERROR(EXP(0.15*(SQRT(BH9)-0.5)/(0.5*0.5)),"") | CA9: =IFERROR(IF(BY9>=1,1E9,BY9/(1-BY9)*BZ9),"") | CB9: =IFERROR(CA9/(1+CA9),"") | CC9: =BH9 | CD9: =BN9 | CE9: =CB9 | CF9: True. Phrased as felt reality not statistic.
A10: 8 | B10: Moroccan public hospitals are significantly understaffed relative to patient volume. | C10: Health | D10: 0.85 | E10: 0.85 | F10: 0.75 | G10: 0.82 | H10: =IFERROR(AVERAGE(D10,E10,F10,G10),"") | I10: 0.7 | J10: 0.65 | K10: 0.7 | L10: 0.68 | M10: =IFERROR(AVERAGE(I10,J10,K10,L10),"") | N10: 0.6 | O10: 0.8 | P10: =IFERROR(IF(H10=0,0,H10^(H10^(-0.5)))*SQRT(M10)*((4*N10+O10)/5),"") | Q10: 0.28 | R10: 0.92 | S10: 0.88 | T10: 0.82 | U10: =IFERROR(((Q10^1.4+T10)/2)*R10*(1-EXP(-4.605*S10)),"") | V10: 0.65 | W10: 0.7 | X10: 0.6 | Y10: 0.72 | Z10: 0.45 | AA10: 0.72 | AB10: =IFERROR(Z10*(Y10*AA10^1.1)^1.1*((3*V10+2*W10+X10)/6)^0.5,"") | AC10: =IFERROR(SQRT(AB10),"") | AD10: 0.7 | AE10: 0.38 | AF10: =IFERROR(AE10*(1-AE10*H10),"") | AG10: 0.65 | AH10: 0.8 | AI10: 0.72 | AJ10: =IFERROR(AH10^2.1*AG10^0.2*(2*AF10+3*AI10+AD10)/6,"") | AK10: =IFERROR(SQRT(AJ10),"") | AL10: 0.18 | AM10: =IFERROR(1-EXP(-AL10),"") | AN10: =IFERROR(4.18*AM10^0.7*(1-AM10)^1.5,"") | AO10: 0.65 | AP10: 0.5 | AQ10: 0.63 | AR10: 0.82 | AS10: =IFERROR(AN10^(1-AO10)*AP10*(4*AQ10*(1-AQ10))*AR10^1.15,"") | AT10: =IFERROR(AS10^(1/3),"") | AU10: 1.8 | AV10: 3 | AW10: =IFERROR(IF(AV10<=1,AU10,AU10*(1+(AV10-1)*0.6)),"") | AX10: 0.88 | AY10: 0.38 | AZ10: 0.5 | BA10: =IFERROR(AZ10/(1-AZ10),"") | BB10: =IFERROR(EXP((P10-0.301)/(0.301*(1-0.301))),"") | BC10: =IFERROR(EXP((U10-0.354)/(0.354*(1-0.354))),"") | BD10: =IFERROR(AW10,"") | BE10: =IFERROR(EXP((AX10-0.75)/(0.75*(1-0.75))),"") | BF10: =IFERROR(EXP((AY10-0.5)/(0.5*(1-0.5))),"") | BG10: =IFERROR(BA10*BB10*BC10*BD10*BE10*BF10,"") | BH10: =IFERROR(BG10/(1+BG10),"") | BI10: =IFERROR(IF(BH10>=1,1E9,BH10/(1-BH10)),"") | BJ10: =IFERROR(EXP((AC10-0.372)/(0.372*(1-0.372))),"") | BK10: =IFERROR(EXP((AK10-0.415)/(0.415*(1-0.415))),"") | BL10: =IFERROR(EXP((AT10-0.405)/(0.405*(1-0.405))),"") | BM10: =IFERROR(BI10*BJ10*BK10*BL10,"") | BN10: =IFERROR(BM10/(1+BM10),"") | BO10: =IFERROR(IF(AC10>=1,0.999,1-EXP(1-(1-AC10)^(-0.8))),"") | BP10: =IFERROR(IF(AK10>=1,0.999,1-EXP(1-(1-AK10)^(-0.75))),"") | BQ10: =IFERROR(1-EXP(-AL10*(1+AL10)),"") | BR10: =IFERROR(BQ10^(1-AO10)*AP10*(4*AQ10*(1-AQ10))*AR10^1.15,"") | BS10: =IFERROR(IF(BR10^(1/3)>=1,0.999,1-EXP(1-(1-BR10^(1/3))^(-0.7))),"") | BT10: =1 | BU10: =IFERROR(EXP((BO10-0.372)/(0.372*(1-0.372))),"") | BV10: =IFERROR(EXP((BP10-0.415)/(0.415*(1-0.415))),"") | BW10: =IFERROR(EXP((BS10-0.405)/(0.405*(1-0.405))),"") | BX10: =IFERROR(BT10*BU10*BV10*BW10,"") | BY10: =IFERROR(BX10/(1+BX10),"") | BZ10: =IFERROR(EXP(0.15*(SQRT(BH10)-0.5)/(0.5*0.5)),"") | CA10: =IFERROR(IF(BY10>=1,1E9,BY10/(1-BY10)*BZ10),"") | CB10: =IFERROR(CA10/(1+CA10),"") | CC10: =BH10 | CD10: =BN10 | CE10: =CB10 | CF10: Universally experienced. Highest confidence in this cluster.
A11: 9 | B11: Black seed (habba sawda) has proven anti-inflammatory and antioxidant properties supported by scientific research. | C11: Health | D11: 0.78 | E11: 0.62 | F11: 0.72 | G11: 0.78 | H11: =IFERROR(AVERAGE(D11,E11,F11,G11),"") | I11: 0.72 | J11: 0.68 | K11: 0.6 | L11: 0.55 | M11: =IFERROR(AVERAGE(I11,J11,K11,L11),"") | N11: 0.55 | O11: 0.65 | P11: =IFERROR(IF(H11=0,0,H11^(H11^(-0.5)))*SQRT(M11)*((4*N11+O11)/5),"") | Q11: 0.45 | R11: 0.82 | S11: 0.85 | T11: 0.72 | U11: =IFERROR(((Q11^1.4+T11)/2)*R11*(1-EXP(-4.605*S11)),"") | V11: 0.6 | W11: 0.65 | X11: 0.6 | Y11: 0.68 | Z11: 0.4 | AA11: 0.68 | AB11: =IFERROR(Z11*(Y11*AA11^1.1)^1.1*((3*V11+2*W11+X11)/6)^0.5,"") | AC11: =IFERROR(SQRT(AB11),"") | AD11: 0.6 | AE11: 0.3 | AF11: =IFERROR(AE11*(1-AE11*H11),"") | AG11: 0.58 | AH11: 0.65 | AI11: 0.58 | AJ11: =IFERROR(AH11^2.1*AG11^0.2*(2*AF11+3*AI11+AD11)/6,"") | AK11: =IFERROR(SQRT(AJ11),"") | AL11: 0.4 | AM11: =IFERROR(1-EXP(-AL11),"") | AN11: =IFERROR(4.18*AM11^0.7*(1-AM11)^1.5,"") | AO11: 0.65 | AP11: 0.48 | AQ11: 0.58 | AR11: 0.62 | AS11: =IFERROR(AN11^(1-AO11)*AP11*(4*AQ11*(1-AQ11))*AR11^1.15,"") | AT11: =IFERROR(AS11^(1/3),"") | AU11: 2.5 | AV11: 3 | AW11: =IFERROR(IF(AV11<=1,AU11,AU11*(1+(AV11-1)*0.6)),"") | AX11: 0.72 | AY11: 0.55 | AZ11: 0.5 | BA11: =IFERROR(AZ11/(1-AZ11),"") | BB11: =IFERROR(EXP((P11-0.301)/(0.301*(1-0.301))),"") | BC11: =IFERROR(EXP((U11-0.354)/(0.354*(1-0.354))),"") | BD11: =IFERROR(AW11,"") | BE11: =IFERROR(EXP((AX11-0.75)/(0.75*(1-0.75))),"") | BF11: =IFERROR(EXP((AY11-0.5)/(0.5*(1-0.5))),"") | BG11: =IFERROR(BA11*BB11*BC11*BD11*BE11*BF11,"") | BH11: =IFERROR(BG11/(1+BG11),"") | BI11: =IFERROR(IF(BH11>=1,1E9,BH11/(1-BH11)),"") | BJ11: =IFERROR(EXP((AC11-0.372)/(0.372*(1-0.372))),"") | BK11: =IFERROR(EXP((AK11-0.415)/(0.415*(1-0.415))),"") | BL11: =IFERROR(EXP((AT11-0.405)/(0.405*(1-0.405))),"") | BM11: =IFERROR(BI11*BJ11*BK11*BL11,"") | BN11: =IFERROR(BM11/(1+BM11),"") | BO11: =IFERROR(IF(AC11>=1,0.999,1-EXP(1-(1-AC11)^(-0.8))),"") | BP11: =IFERROR(IF(AK11>=1,0.999,1-EXP(1-(1-AK11)^(-0.75))),"") | BQ11: =IFERROR(1-EXP(-AL11*(1+AL11)),"") | BR11: =IFERROR(BQ11^(1-AO11)*AP11*(4*AQ11*(1-AQ11))*AR11^1.15,"") | BS11: =IFERROR(IF(BR11^(1/3)>=1,0.999,1-EXP(1-(1-BR11^(1/3))^(-0.7))),"") | BT11: =1 | BU11: =IFERROR(EXP((BO11-0.372)/(0.372*(1-0.372))),"") | BV11: =IFERROR(EXP((BP11-0.415)/(0.415*(1-0.415))),"") | BW11: =IFERROR(EXP((BS11-0.405)/(0.405*(1-0.405))),"") | BX11: =IFERROR(BT11*BU11*BV11*BW11,"") | BY11: =IFERROR(BX11/(1+BX11),"") | BZ11: =IFERROR(EXP(0.15*(SQRT(BH11)-0.5)/(0.5*0.5)),"") | CA11: =IFERROR(IF(BY11>=1,1E9,BY11/(1-BY11)*BZ11),"") | CB11: =IFERROR(CA11/(1+CA11),"") | CC11: =BH11 | CD11: =BN11 | CE11: =CB11 | CF11: Some financial bias in source. True but commercially overstated. Medium awareness.
A12: 10 | B12: Fasting during Ramadan has measurable metabolic health benefits supported by scientific studies. | C12: Health | D12: 0.85 | E12: 0.85 | F12: 0.8 | G12: 0.85 | H12: =IFERROR(AVERAGE(D12,E12,F12,G12),"") | I12: 0.78 | J12: 0.72 | K12: 0.7 | L12: 0.65 | M12: =IFERROR(AVERAGE(I12,J12,K12,L12),"") | N12: 0.6 | O12: 0.75 | P12: =IFERROR(IF(H12=0,0,H12^(H12^(-0.5)))*SQRT(M12)*((4*N12+O12)/5),"") | Q12: 0.4 | R12: 0.88 | S12: 0.9 | T12: 0.78 | U12: =IFERROR(((Q12^1.4+T12)/2)*R12*(1-EXP(-4.605*S12)),"") | V12: 0.65 | W12: 0.72 | X12: 0.6 | Y12: 0.72 | Z12: 0.48 | AA12: 0.7 | AB12: =IFERROR(Z12*(Y12*AA12^1.1)^1.1*((3*V12+2*W12+X12)/6)^0.5,"") | AC12: =IFERROR(SQRT(AB12),"") | AD12: 0.72 | AE12: 0.35 | AF12: =IFERROR(AE12*(1-AE12*H12),"") | AG12: 0.68 | AH12: 0.8 | AI12: 0.68 | AJ12: =IFERROR(AH12^2.1*AG12^0.2*(2*AF12+3*AI12+AD12)/6,"") | AK12: =IFERROR(SQRT(AJ12),"") | AL12: 0.3 | AM12: =IFERROR(1-EXP(-AL12),"") | AN12: =IFERROR(4.18*AM12^0.7*(1-AM12)^1.5,"") | AO12: 0.75 | AP12: 0.52 | AQ12: 0.68 | AR12: 0.72 | AS12: =IFERROR(AN12^(1-AO12)*AP12*(4*AQ12*(1-AQ12))*AR12^1.15,"") | AT12: =IFERROR(AS12^(1/3),"") | AU12: 3 | AV12: 4 | AW12: =IFERROR(IF(AV12<=1,AU12,AU12*(1+(AV12-1)*0.6)),"") | AX12: 0.85 | AY12: 0.62 | AZ12: 0.5 | BA12: =IFERROR(AZ12/(1-AZ12),"") | BB12: =IFERROR(EXP((P12-0.301)/(0.301*(1-0.301))),"") | BC12: =IFERROR(EXP((U12-0.354)/(0.354*(1-0.354))),"") | BD12: =IFERROR(AW12,"") | BE12: =IFERROR(EXP((AX12-0.75)/(0.75*(1-0.75))),"") | BF12: =IFERROR(EXP((AY12-0.5)/(0.5*(1-0.5))),"") | BG12: =IFERROR(BA12*BB12*BC12*BD12*BE12*BF12,"") | BH12: =IFERROR(BG12/(1+BG12),"") | BI12: =IFERROR(IF(BH12>=1,1E9,BH12/(1-BH12)),"") | BJ12: =IFERROR(EXP((AC12-0.372)/(0.372*(1-0.372))),"") | BK12: =IFERROR(EXP((AK12-0.415)/(0.415*(1-0.415))),"") | BL12: =IFERROR(EXP((AT12-0.405)/(0.405*(1-0.405))),"") | BM12: =IFERROR(BI12*BJ12*BK12*BL12,"") | BN12: =IFERROR(BM12/(1+BM12),"") | BO12: =IFERROR(IF(AC12>=1,0.999,1-EXP(1-(1-AC12)^(-0.8))),"") | BP12: =IFERROR(IF(AK12>=1,0.999,1-EXP(1-(1-AK12)^(-0.75))),"") | BQ12: =IFERROR(1-EXP(-AL12*(1+AL12)),"") | BR12: =IFERROR(BQ12^(1-AO12)*AP12*(4*AQ12*(1-AQ12))*AR12^1.15,"") | BS12: =IFERROR(IF(BR12^(1/3)>=1,0.999,1-EXP(1-(1-BR12^(1/3))^(-0.7))),"") | BT12: =1 | BU12: =IFERROR(EXP((BO12-0.372)/(0.372*(1-0.372))),"") | BV12: =IFERROR(EXP((BP12-0.415)/(0.415*(1-0.415))),"") | BW12: =IFERROR(EXP((BS12-0.405)/(0.405*(1-0.405))),"") | BX12: =IFERROR(BT12*BU12*BV12*BW12,"") | BY12: =IFERROR(BX12/(1+BX12),"") | BZ12: =IFERROR(EXP(0.15*(SQRT(BH12)-0.5)/(0.5*0.5)),"") | CA12: =IFERROR(IF(BY12>=1,1E9,BY12/(1-BY12)*BZ12),"") | CB12: =IFERROR(CA12/(1+CA12),"") | CC12: =BH12 | CD12: =BN12 | CE12: =CB12 | CF12: True. Receiver knows this well. Emotionally positive (Ramadan). High scientific support.
A13: 11 | B13: Sleeping with your phone under your pillow causes brain damage over time. | C13: Health | D13: 0.8 | E13: 0.8 | F13: 0.8 | G13: 0.8 | H13: =IFERROR(AVERAGE(D13,E13,F13,G13),"") | I13: 0.2 | J13: 0.15 | K13: 0.1 | L13: 0.15 | M13: =IFERROR(AVERAGE(I13,J13,K13,L13),"") | N13: 0.3 | O13: 0.6 | P13: =IFERROR(IF(H13=0,0,H13^(H13^(-0.5)))*SQRT(M13)*((4*N13+O13)/5),"") | Q13: 0.55 | R13: 0.65 | S13: 0.72 | T13: 0.6 | U13: =IFERROR(((Q13^1.4+T13)/2)*R13*(1-EXP(-4.605*S13)),"") | V13: 0.55 | W13: 0.6 | X13: 0.6 | Y13: 0.6 | Z13: 0.35 | AA13: 0.75 | AB13: =IFERROR(Z13*(Y13*AA13^1.1)^1.1*((3*V13+2*W13+X13)/6)^0.5,"") | AC13: =IFERROR(SQRT(AB13),"") | AD13: 0.55 | AE13: 0.2 | AF13: =IFERROR(AE13*(1-AE13*H13),"") | AG13: 0.55 | AH13: 0.6 | AI13: 0.52 | AJ13: =IFERROR(AH13^2.1*AG13^0.2*(2*AF13+3*AI13+AD13)/6,"") | AK13: =IFERROR(SQRT(AJ13),"") | AL13: 0.65 | AM13: =IFERROR(1-EXP(-AL13),"") | AN13: =IFERROR(4.18*AM13^0.7*(1-AM13)^1.5,"") | AO13: 0.6 | AP13: 0.42 | AQ13: 0.52 | AR13: 0.6 | AS13: =IFERROR(AN13^(1-AO13)*AP13*(4*AQ13*(1-AQ13))*AR13^1.15,"") | AT13: =IFERROR(AS13^(1/3),"") | AU13: 1 | AV13: 1 | AW13: =IFERROR(IF(AV13<=1,AU13,AU13*(1+(AV13-1)*0.6)),"") | AX13: 0.25 | AY13: 0.08 | AZ13: 0.5 | BA13: =IFERROR(AZ13/(1-AZ13),"") | BB13: =IFERROR(EXP((P13-0.301)/(0.301*(1-0.301))),"") | BC13: =IFERROR(EXP((U13-0.354)/(0.354*(1-0.354))),"") | BD13: =IFERROR(AW13,"") | BE13: =IFERROR(EXP((AX13-0.75)/(0.75*(1-0.75))),"") | BF13: =IFERROR(EXP((AY13-0.5)/(0.5*(1-0.5))),"") | BG13: =IFERROR(BA13*BB13*BC13*BD13*BE13*BF13,"") | BH13: =IFERROR(BG13/(1+BG13),"") | BI13: =IFERROR(IF(BH13>=1,1E9,BH13/(1-BH13)),"") | BJ13: =IFERROR(EXP((AC13-0.372)/(0.372*(1-0.372))),"") | BK13: =IFERROR(EXP((AK13-0.415)/(0.415*(1-0.415))),"") | BL13: =IFERROR(EXP((AT13-0.405)/(0.405*(1-0.405))),"") | BM13: =IFERROR(BI13*BJ13*BK13*BL13,"") | BN13: =IFERROR(BM13/(1+BM13),"") | BO13: =IFERROR(IF(AC13>=1,0.999,1-EXP(1-(1-AC13)^(-0.8))),"") | BP13: =IFERROR(IF(AK13>=1,0.999,1-EXP(1-(1-AK13)^(-0.75))),"") | BQ13: =IFERROR(1-EXP(-AL13*(1+AL13)),"") | BR13: =IFERROR(BQ13^(1-AO13)*AP13*(4*AQ13*(1-AQ13))*AR13^1.15,"") | BS13: =IFERROR(IF(BR13^(1/3)>=1,0.999,1-EXP(1-(1-BR13^(1/3))^(-0.7))),"") | BT13: =1 | BU13: =IFERROR(EXP((BO13-0.372)/(0.372*(1-0.372))),"") | BV13: =IFERROR(EXP((BP13-0.415)/(0.415*(1-0.415))),"") | BW13: =IFERROR(EXP((BS13-0.405)/(0.405*(1-0.405))),"") | BX13: =IFERROR(BT13*BU13*BV13*BW13,"") | BY13: =IFERROR(BX13/(1+BX13),"") | BZ13: =IFERROR(EXP(0.15*(SQRT(BH13)-0.5)/(0.5*0.5)),"") | CA13: =IFERROR(IF(BY13>=1,1E9,BY13/(1-BY13)*BZ13),"") | CB13: =IFERROR(CA13/(1+CA13),"") | CC13: =BH13 | CD13: =BN13 | CE13: =CB13 | CF13: False. Fading WhatsApp myth. Low expertise source. Rising opposition as it fades.
A14: 12 | B14: Argan oil applied to the skin has scientifically supported antioxidant properties. | C14: Health | D14: 0.72 | E14: 0.58 | F14: 0.72 | G14: 0.75 | H14: =IFERROR(AVERAGE(D14,E14,F14,G14),"") | I14: 0.68 | J14: 0.65 | K14: 0.58 | L14: 0.52 | M14: =IFERROR(AVERAGE(I14,J14,K14,L14),"") | N14: 0.52 | O14: 0.68 | P14: =IFERROR(IF(H14=0,0,H14^(H14^(-0.5)))*SQRT(M14)*((4*N14+O14)/5),"") | Q14: 0.42 | R14: 0.82 | S14: 0.85 | T14: 0.7 | U14: =IFERROR(((Q14^1.4+T14)/2)*R14*(1-EXP(-4.605*S14)),"") | V14: 0.6 | W14: 0.65 | X14: 0.6 | Y14: 0.65 | Z14: 0.42 | AA14: 0.68 | AB14: =IFERROR(Z14*(Y14*AA14^1.1)^1.1*((3*V14+2*W14+X14)/6)^0.5,"") | AC14: =IFERROR(SQRT(AB14),"") | AD14: 0.58 | AE14: 0.28 | AF14: =IFERROR(AE14*(1-AE14*H14),"") | AG14: 0.58 | AH14: 0.68 | AI14: 0.55 | AJ14: =IFERROR(AH14^2.1*AG14^0.2*(2*AF14+3*AI14+AD14)/6,"") | AK14: =IFERROR(SQRT(AJ14),"") | AL14: 0.45 | AM14: =IFERROR(1-EXP(-AL14),"") | AN14: =IFERROR(4.18*AM14^0.7*(1-AM14)^1.5,"") | AO14: 0.65 | AP14: 0.48 | AQ14: 0.58 | AR14: 0.58 | AS14: =IFERROR(AN14^(1-AO14)*AP14*(4*AQ14*(1-AQ14))*AR14^1.15,"") | AT14: =IFERROR(AS14^(1/3),"") | AU14: 2.2 | AV14: 3 | AW14: =IFERROR(IF(AV14<=1,AU14,AU14*(1+(AV14-1)*0.6)),"") | AX14: 0.75 | AY14: 0.52 | AZ14: 0.5 | BA14: =IFERROR(AZ14/(1-AZ14),"") | BB14: =IFERROR(EXP((P14-0.301)/(0.301*(1-0.301))),"") | BC14: =IFERROR(EXP((U14-0.354)/(0.354*(1-0.354))),"") | BD14: =IFERROR(AW14,"") | BE14: =IFERROR(EXP((AX14-0.75)/(0.75*(1-0.75))),"") | BF14: =IFERROR(EXP((AY14-0.5)/(0.5*(1-0.5))),"") | BG14: =IFERROR(BA14*BB14*BC14*BD14*BE14*BF14,"") | BH14: =IFERROR(BG14/(1+BG14),"") | BI14: =IFERROR(IF(BH14>=1,1E9,BH14/(1-BH14)),"") | BJ14: =IFERROR(EXP((AC14-0.372)/(0.372*(1-0.372))),"") | BK14: =IFERROR(EXP((AK14-0.415)/(0.415*(1-0.415))),"") | BL14: =IFERROR(EXP((AT14-0.405)/(0.405*(1-0.405))),"") | BM14: =IFERROR(BI14*BJ14*BK14*BL14,"") | BN14: =IFERROR(BM14/(1+BM14),"") | BO14: =IFERROR(IF(AC14>=1,0.999,1-EXP(1-(1-AC14)^(-0.8))),"") | BP14: =IFERROR(IF(AK14>=1,0.999,1-EXP(1-(1-AK14)^(-0.75))),"") | BQ14: =IFERROR(1-EXP(-AL14*(1+AL14)),"") | BR14: =IFERROR(BQ14^(1-AO14)*AP14*(4*AQ14*(1-AQ14))*AR14^1.15,"") | BS14: =IFERROR(IF(BR14^(1/3)>=1,0.999,1-EXP(1-(1-BR14^(1/3))^(-0.7))),"") | BT14: =1 | BU14: =IFERROR(EXP((BO14-0.372)/(0.372*(1-0.372))),"") | BV14: =IFERROR(EXP((BP14-0.415)/(0.415*(1-0.415))),"") | BW14: =IFERROR(EXP((BS14-0.405)/(0.405*(1-0.405))),"") | BX14: =IFERROR(BT14*BU14*BV14*BW14,"") | BY14: =IFERROR(BX14/(1+BX14),"") | BZ14: =IFERROR(EXP(0.15*(SQRT(BH14)-0.5)/(0.5*0.5)),"") | CA14: =IFERROR(IF(BY14>=1,1E9,BY14/(1-BY14)*BZ14),"") | CB14: =IFERROR(CA14/(1+CA14),"") | CC14: =BH14 | CD14: =BN14 | CE14: =CB14 | CF14: Some commercial bias but neutral-ish. True. Medium-high awareness among Moroccans.
... A102: 100 | B102: Free will is an illusion — every choice a person makes is the product of prior causes they did not choose. | C102: Big Ideas | D102: 0.8 | E102: 0.8 | F102: 0.8 | G102: 0.8 | H102: =IFERROR(AVERAGE(D102,E102,F102,G102),"") | I102: 0.45 | J102: 0.42 | K102: 0.4 | L102: 0.38 | M102: =IFERROR(AVERAGE(I102,J102,K102,L102),"") | N102: 0.48 | O102: 0.6 | P102: =IFERROR(IF(H102=0,0,H102^(H102^(-0.5)))*SQRT(M102)*((4*N102+O102)/5),"") | Q102: 0.65 | R102: 0.8 | S102: 0.03 | T102: 0.7 | U102: =IFERROR(((Q102^1.4+T102)/2)*R102*(1-EXP(-4.605*S102)),"") | V102: 0.58 | W102: 0.62 | X102: 0.6 | Y102: 0.65 | Z102: 0.42 | AA102: 0.65 | AB102: =IFERROR(Z102*(Y102*AA102^1.1)^1.1*((3*V102+2*W102+X102)/6)^0.5,"") | AC102: =IFERROR(SQRT(AB102),"") | AD102: 0.58 | AE102: 0.25 | AF102: =IFERROR(AE102*(1-AE102*H102),"") | AG102: 0.58 | AH102: 0.62 | AI102: 0.65 | AJ102: =IFERROR(AH102^2.1*AG102^0.2*(2*AF102+3*AI102+AD102)/6,"") | AK102: =IFERROR(SQRT(AJ102),"") | AL102: 1 | AM102: =IFERROR(1-EXP(-AL102),"") | AN102: =IFERROR(4.18*AM102^0.7*(1-AM102)^1.5,"") | AO102: 0.5 | AP102: 0.48 | AQ102: 0.7 | AR102: 0.65 | AS102: =IFERROR(AN102^(1-AO102)*AP102*(4*AQ102*(1-AQ102))*AR102^1.15,"") | AT102: =IFERROR(AS102^(1/3),"") | AU102: 1 | AV102: 1 | AW102: =IFERROR(IF(AV102<=1,AU102,AU102*(1+(AV102-1)*0.6)),"") | AX102: 0.35 | AY102: 0.05 | AZ102: 0.5 | BA102: =IFERROR(AZ102/(1-AZ102),"") | BB102: =IFERROR(EXP((P102-0.301)/(0.301*(1-0.301))),"") | BC102: =IFERROR(EXP((U102-0.354)/(0.354*(1-0.354))),"") | BD102: =IFERROR(AW102,"") | BE102: =IFERROR(EXP((AX102-0.75)/(0.75*(1-0.75))),"") | BF102: =IFERROR(EXP((AY102-0.5)/(0.5*(1-0.5))),"") | BG102: =IFERROR(BA102*BB102*BC102*BD102*BE102*BF102,"") | BH102: =IFERROR(BG102/(1+BG102),"") | BI102: =IFERROR(IF(BH102>=1,1E9,BH102/(1-BH102)),"") | BJ102: =IFERROR(EXP((AC102-0.372)/(0.372*(1-0.372))),"") | BK102: =IFERROR(EXP((AK102-0.415)/(0.415*(1-0.415))),"") | BL102: =IFERROR(EXP((AT102-0.405)/(0.405*(1-0.405))),"") | BM102: =IFERROR(BI102*BJ102*BK102*BL102,"") | BN102: =IFERROR(BM102/(1+BM102),"") | BO102: =IFERROR(IF(AC102>=1,0.999,1-EXP(1-(1-AC102)^(-0.8))),"") | BP102: =IFERROR(IF(AK102>=1,0.999,1-EXP(1-(1-AK102)^(-0.75))),"") | BQ102: =IFERROR(1-EXP(-AL102*(1+AL102)),"") | BR102: =IFERROR(BQ102^(1-AO102)*AP102*(4*AQ102*(1-AQ102))*AR102^1.15,"") | BS102: =IFERROR(IF(BR102^(1/3)>=1,0.999,1-EXP(1-(1-BR102^(1/3))^(-0.7))),"") | BT102: =1 | BU102: =IFERROR(EXP((BO102-0.372)/(0.372*(1-0.372))),"") | BV102: =IFERROR(EXP((BP102-0.415)/(0.415*(1-0.415))),"") | BW102: =IFERROR(EXP((BS102-0.405)/(0.405*(1-0.405))),"") | BX102: =IFERROR(BT102*BU102*BV102*BW102,"") | BY102: =IFERROR(BX102/(1+BX102),"") | BZ102: =IFERROR(EXP(0.15*(SQRT(BH102)-0.5)/(0.5*0.5)),"") | CA102: =IFERROR(IF(BY102>=1,1E9,BY102/(1-BY102)*BZ102),"") | CB102: =IFERROR(CA102/(1+CA102),"") | CC102: =BH102 | CD102: =BN102 | CE102: =CB102 | CF102: Near-unfalsifiable. People divided. Existentialism as daily life. H_f=0.03.

Sheet Summary
A1: SCORING SUMMARY — Pre-Registration Output
A2: # | B2: Statement | C2: T_abs | D2: T_perc | E2: I | F2: Domain
A3: 1 | B3: In many Moroccan public hospitals, patients are told to buy their own medicine from a pharmacy because the hospital has run out. | C3: =Scoring!CC3 | D3: =Scoring!CD3 | E3: =Scoring!CE3 | F3: Health
A4: 2 | B4: Getting a specialist appointment in a Moroccan public hospital can take several months to over a year. | C4: =Scoring!CC4 | D4: =Scoring!CD4 | E4: =Scoring!CE4 | F4: Health
A5: 3 | B5: The quality of care you receive in a Moroccan hospital depends more on who you know than on your medical card. | C5: =Scoring!CC5 | D5: =Scoring!CD5 | E5: =Scoring!CE5 | F5: Health
A6: 4 | B6: There are regions in Morocco where reaching the nearest doctor means a long, difficult trip, not a quick visit. | C6: =Scoring!CC6 | D6: =Scoring!CD6 | E6: =Scoring!CE6 | F6: Health
A7: 5 | B7: A doctor in a Moroccan public hospital sees so many patients per day that each consultation gets rushed down to just a few minutes. | C7: =Scoring!CC7 | D7: =Scoring!CD7 | E7: =Scoring!CE7 | F7: Health
A8: 6 | B8: Private clinics in Morocco are expensive but often face the same medicine shortages as public hospitals. | C8: =Scoring!CC8 | D8: =Scoring!CD8 | E8: =Scoring!CE8 | F8: Health
A9: 7 | B9: Morocco has far fewer doctors per person than international health bodies consider safe. | C9: =Scoring!CC9 | D9: =Scoring!CD9 | E9: =Scoring!CE9 | F9: Health
A10: 8 | B10: Moroccan public hospitals are significantly understaffed relative to patient volume. | C10: =Scoring!CC10 | D10: =Scoring!CD10 | E10: =Scoring!CE10 | F10: Health
A11: 9 | B11: Black seed (habba sawda) has proven anti-inflammatory and antioxidant properties supported by scientific research. | C11: =Scoring!CC11 | D11: =Scoring!CD11 | E11: =Scoring!CE11 | F11: Health
A12: 10 | B12: Fasting during Ramadan has measurable metabolic health benefits supported by scientific studies. | C12: =Scoring!CC12 | D12: =Scoring!CD12 | E12: =Scoring!CE12 | F12: Health
A13: 11 | B13: Sleeping with your phone under your pillow causes brain damage over time. | C13: =Scoring!CC13 | D13: =Scoring!CD13 | E13: =Scoring!CE13 | F13: Health
A14: 12 | B14: Argan oil applied to the skin has scientifically supported antioxidant properties. | C14: =Scoring!CC14 | D14: =Scoring!CD14 | E14: =Scoring!CE14 | F14: Health
... A102: 100 | B102: Free will is an illusion — every choice a person makes is the product of prior causes they did not choose. | C102: =Scoring!CC102 | D102: =Scoring!CD102 | E102: =Scoring!CE102 | F102: Big Ideas
